Workbook

Sheet TS_Imports
A1: HS6 Code | B1: Product Description | C1: 2016 | D1: 2017 | E1: 2018 | F1: 2019 | G1: 2020 | H1: 2021 | I1: 2022 | J1: 2023 | K1: 2024 | L1: 2025 | M1: Product Category
A2: 8542 | B2: Electronic integrated circuits; parts thereof | C2: 92.55 | D2: 123.06 | E2: 101.01 | F2: 97.75 | G2: 100.71 | H2: 151.05 | I2: 215.05 | J2: 313.52 | K2: 420.33 | L2: 445.84 | M2: =VLOOKUP(A2,Product_Mapping!$B:$D,3,FALSE) -> Electrical
A3: 8536 | B3: Electrical apparatus for switching or protecting electrical circuits, or for making connections to or in electrical circuits, e.g., switches, relays, fuses, surge suppressors, plugs, sockets, lamp holders and junction boxes, for a voltage <= 1.000 V (excl. control desks, cabinets, panels etc. of heading 8537) | C3: 115.76 | D3: 129.6 | E3: 131.68 | F3: 108.33 | G3: 108.49 | H3: 154.6 | I3: 184.61 | J3: 194.14 | K3: 192.44 | L3: 247.91 | M3: =VLOOKUP(A3,Product_Mapping!$B:$D,3,FALSE) -> Electrical
A4: 8541 | B4: Semiconductor devices "e.g. diodes, transistors, semiconductor-based transducers"; photosensitive semiconductor devices, incl. photovoltaic cells whether or not assembled in modules or made up into panels (excl. photovoltaic generators); light emitting diodes "LED", whether or not assembled with other light-emitting diodes "LED"; mounted piezoelectric crystals; parts thereof | C4: 137.75 | D4: 112.73 | E4: 93.91 | F4: 114.07 | G4: 98.8 | H4: 111.71 | I4: 158.28 | J4: 222.86 | K4: 184.92 | L4: 219.5 | M4: =VLOOKUP(A4,Product_Mapping!$B:$D,3,FALSE) -> Electrical
A5: 8504 | B5: Electrical transformers, static converters, e.g. rectifiers, and inductors; parts thereof | C5: 59.42 | D5: 80.12 | E5: 87.57 | F5: 95.71 | G5: 60.61 | H5: 90.03 | I5: 84.43 | J5: 111.37 | K5: 94.92 | L5: 158.45 | M5: =VLOOKUP(A5,Product_Mapping!$B:$D,3,FALSE) -> Electrical
A6: 8537 | B6: Boards, panels, consoles, desks, cabinets and other bases, equipped with two or more apparatus of heading 8535 or 8536, for electric control or the distribution of electricity, incl. those incorporating instruments or apparatus of chapter 90, and numerical control apparatus (excl. switching apparatus for line telephony or line telegraphy) | C6: 71 | D6: 72.79 | E6: 105.87 | F6: 74.02 | G6: 55.23 | H6: 114.25 | I6: 130.24 | J6: 111.94 | K6: 115.82 | L6: 132.09 | M6: =VLOOKUP(A6,Product_Mapping!$B:$D,3,FALSE) -> Electrical
A7: 8515 | B7: Electric, incl. electrically heated gas, laser or other light or photon beam, ultrasonic, electron beam, magnetic pulse or plasma arc soldering, brazing or welding machines and apparatus, whether or not capable of cutting; electric machines and apparatus for hot spraying of metals, metal carbides or cermets; parts thereof (excl. guns for spraying hot materials of heading 8424) | C7: 48.79 | D7: 33.12 | E7: 41.69 | F7: 86.16 | G7: 52.85 | H7: 70.12 | I7: 47.4 | J7: 82.1 | K7: 104.45 | L7: 115.28 | M7: =VLOOKUP(A7,Product_Mapping!$B:$D,3,FALSE) -> Electrical
A8: 8532 | B8: Electrical capacitors, fixed, variable or adjustable "pre-set"; parts thereof | C8: 39.22 | D8: 38.83 | E8: 31.69 | F8: 40.29 | G8: 29.83 | H8: 31.94 | I8: 49.54 | J8: 62.62 | K8: 87.49 | L8: 115.1 | M8: =VLOOKUP(A8,Product_Mapping!$B:$D,3,FALSE) -> Electrical
A9: 8511 | B9: Electrical ignition or starting equipment of a kind used for spark-ignition or compression-ignition internal combustion engines, e.g. ignition magnetos, magneto-dynamos, ignition coils, sparking plugs, glow plugs and starter motors; generators, e.g. dynamos and alternators, and cut-outs of a kind used in conjunction with such engines; parts thereof | C9: 42.34 | D9: 46.24 | E9: 47.24 | F9: 33.45 | G9: 24.31 | H9: 41.27 | I9: 69.78 | J9: 85.24 | K9: 98.95 | L9: 107.02 | M9: =VLOOKUP(A9,Product_Mapping!$B:$D,3,FALSE) -> Electrical
A10: 8507 | B10: Electric accumulators, incl. separators therefor, whether or not square or rectangular; parts thereof (excl. spent and those of unhardened rubber or textiles) | C10: 25.83 | D10: 31.08 | E10: 36.38 | F10: 30.89 | G10: 31.89 | H10: 56.74 | I10: 85.42 | J10: 86.64 | K10: 65.35 | L10: 105.78 | M10: =VLOOKUP(A10,Product_Mapping!$B:$D,3,FALSE) -> Electrical
A11: 8501 | B11: Electric motors and generators (excl. generating sets) | C11: 74.47 | D11: 104.29 | E11: 111.55 | F11: 94.32 | G11: 47.97 | H11: 64.32 | I11: 73.58 | J11: 84.01 | K11: 74.35 | L11: 79.78 | M11: =VLOOKUP(A11,Product_Mapping!$B:$D,3,FALSE) -> Electrical
A12: 8525 | B12: Transmission apparatus for radio-broadcasting or television, whether or not incorporating reception apparatus or sound recording or reproducing apparatus; television cameras, digital cameras and video camera recorders | C12: 75.94 | D12: 97.92 | E12: 84.09 | F12: 96.91 | G12: 51 | H12: 61.5 | I12: 79.61 | J12: 63.91 | K12: 50.55 | L12: 76.8 | M12: =VLOOKUP(A12,Product_Mapping!$B:$D,3,FALSE) -> Electrical
A13: 8538 | B13: Parts suitable for use solely or principally with the apparatus of heading 8535, 8536 or 8537, n.e.s. | C13: 45.12 | D13: 44.06 | E13: 50.34 | F13: 63.21 | G13: 45.5 | H13: 57.19 | I13: 59.03 | J13: 66.87 | K13: 59.68 | L13: 73.69 | M13: =VLOOKUP(A13,Product_Mapping!$B:$D,3,FALSE) -> Electrical
... A83: 6811 | B83: Articles of asbestos-cement, cellulose fibre-cement or the like | C83: 0 | D83: 0.02 | E83: 0.08 | F83: 0.04 | G83: 0 | H83: 0.02 | I83: 0.05 | J83: 0.15 | K83: 0 | L83: 0.11 | M83: =VLOOKUP(A83,Product_Mapping!$B:$D,3,FALSE) -> Decorative Materials
A84: 6810 | B84: Articles of cement, concrete or artificial stone, whether or not reinforced | C84: 0.03 | D84: 0.02 | E84: 0.15 | F84: ≈ 0 | G84: 0 | H84: 0 | I84: 0 | J84: 0 | K84: 0.03 | L84: 0.1 | M84: =VLOOKUP(A84,Product_Mapping!$B:$D,3,FALSE) -> Decorative Materials
A85: 6802 | B85: Monumental or building stone, natural (excl. slate), worked, and articles; mosaic cubes etc. of natural stone, incl. slate, whether or not on a backing; artificially coloured granules, chippings, powder, of natural stone, incl. slate (excl. setts, curbstones, flagstones; articles of fused basalt and of fired steatite; jewellery, clocks, lamps and parts; buttons, chalks, original sculptures and statuary) | C85: 0.05 | D85: 0.02 | E85: 0.01 | F85: 0.01 | G85: 0.01 | H85: 0 | I85: 0 | J85: 0 | K85: 0 | L85: 0 | M85: =VLOOKUP(A85,Product_Mapping!$B:$D,3,FALSE) -> Decorative Materials
A86: 6803 | B86: Worked slate and articles of slate or of agglomerated slate (excluding slate granules, chippings and powder, mosaic cubes and the like, slate pencils, and ready-to-use slates or boards with writing or drawing surfaces) | C86: 0 | D86: 0 | E86: 0 | F86: ≈ 0 | G86: ≈ 0 | H86: 0 | I86: 0 | J86: ≈ 0 | K86: 0 | L86: 0 | M86: =VLOOKUP(A86,Product_Mapping!$B:$D,3,FALSE) -> Decorative Materials
A87: 6807 | B87: Articles of asphalt or of similar materials, e.g. petroleum bitumen or coal tar pitch | C87: 0.17 | D87: 0.25 | E87: 0 | F87: 0 | G87: 0 | H87: 0.01 | I87: 0 | J87: 0.01 | K87: 0 | L87: 0 | M87: =VLOOKUP(A87,Product_Mapping!$B:$D,3,FALSE) -> Decorative Materials
A88: 6808 | B88: Panels, boards, tiles, blocks and similar articles of vegetable fibre, of straw or of shavings, chips, particles, sawdust or other waste of wood, agglomerated with cement, plaster or other mineral binders (excluding articles of asbestos-cement, cellulose fibre-cement or the like) | C88: 0.02 | D88: 0 | E88: 0 | F88: ≈ 0 | G88: 0 | H88: 0 | I88: 0 | J88: ≈ 0 | K88: 0 | L88: 0 | M88: =VLOOKUP(A88,Product_Mapping!$B:$D,3,FALSE) -> Decorative Materials
A89: 6809 | B89: Articles of plaster or of compositions based on plaster (excl. plaster bandages for straightening fractures, put up for retail sale; plaster splints for the treatment of fractures; lightweight with plaster agglomerated building boards or articles for heat-insulation, sound-insulation or sound absorption; anatomic and other models for demonstration purposes; original sculptures and statuary) | C89: 0 | D89: 0.05 | E89: 0 | F89: 0 | G89: 0 | H89: 0 | I89: 0 | J89: 0 | K89: 0 | L89: 0 | M89: =VLOOKUP(A89,Product_Mapping!$B:$D,3,FALSE) -> Decorative Materials
A90: 6909 | B90: Ceramic wares for laboratory, chemical or other technical uses; ceramic troughs, tubs and similar receptacles used in agriculture; ceramic pots, jars and similar articles used for the conveyance or packing of goods (excl. millstones, polishing stones, grindstones and the like of heading 6804; refractory ceramic goods; household articles; containers for shops; electrical devices, insulators and other insulating fittings) | C90: 3.46 | D90: 9.2 | E90: 12.48 | F90: 7.15 | G90: 8.09 | H90: 13.29 | I90: 11.02 | J90: 20.88 | K90: 16.99 | L90: 21.44 | M90: =VLOOKUP(A90,Product_Mapping!$B:$D,3,FALSE) -> Sanitary
A91: 6903 | B91: Retorts, crucibles, mufflers, nozzles, plugs, supports, cupels, tubes, pipes, sheaths, rods, slide gates and other refractory ceramic goods (excl. those of siliceous fossil meals or of similar siliceous earths, and refractory bricks, blocks, tiles and similar refractory ceramic constructional goods) | C91: 4.31 | D91: 3.68 | E91: 6.47 | F91: 8.17 | G91: 8.71 | H91: 12.58 | I91: 12.66 | J91: 11.78 | K91: 11.76 | L91: 11.41 | M91: =VLOOKUP(A91,Product_Mapping!$B:$D,3,FALSE) -> Sanitary
A92: 6902 | B92: Refractory bricks, blocks, tiles and similar refractory ceramic constructional goods (excl. those of siliceous fossil meals or similar siliceous earths) | C92: 1.89 | D92: 4.25 | E92: 1.38 | F92: 1.3 | G92: 1.94 | H92: 2.88 | I92: 1.43 | J92: 7.39 | K92: 15.09 | L92: 9.3 | M92: =VLOOKUP(A92,Product_Mapping!$B:$D,3,FALSE) -> Sanitary
A93: 6914 | B93: Ceramic articles, n.e.s. | C93: 3.6 | D93: 1.96 | E93: 2.69 | F93: 2.64 | G93: 1.59 | H93: 2.36 | I93: 2.32 | J93: 1.31 | K93: 2.32 | L93: 2.11 | M93: =VLOOKUP(A93,Product_Mapping!$B:$D,3,FALSE) -> Sanitary
A94: 6910 | B94: Ceramic sinks, washbasins, washbasin pedestals, baths, bidets, water closet pans, flushing cisterns, urinals and similar sanitary fixtures (excl. soap dishes, sponge holders, tooth-brush holders, towel hooks and toilet paper holders) | C94: 0.13 | D94: 0.21 | E94: 0.36 | F94: 0.33 | G94: 0.25 | H94: 0.32 | I94: 0.44 | J94: 0.54 | K94: 0.43 | L94: 0.52 | M94: =VLOOKUP(A94,Product_Mapping!$B:$D,3,FALSE) -> Sanitary
A95: 6911 | B95: Tableware, kitchenware, other household articles and toilet articles, of porcelain or china (excl. baths, bidets, sinks and similar sanitary fixtures, statuettes and other ornamental articles, pots, jars, carboys and similar receptacles for the conveyance or packing of goods, and coffee grinders and spice mills with receptacles made of ceramics and working parts of metal) | C95: 0.21 | D95: 0.11 | E95: 0.21 | F95: 0.35 | G95: 0.31 | H95: 0.54 | I95: 0.27 | J95: 0.16 | K95: 0.18 | L95: 0.14 | M95: =VLOOKUP(A95,Product_Mapping!$B:$D,3,FALSE) -> Sanitary
A96: 6912 | B96: Tableware, kitchenware, other household articles and toilet articles, of ceramics other than porcelain or china (excluding baths, bidets, sinks and similar sanitary fixtures, statuettes and other ornamental articles, pots, jars, carboys and similar receptacles for the conveyance or packing of goods, and coffee grinders and spice mills with receptacles made of ceramics and working parts of metal) | C96: 0.04 | D96: 0.02 | E96: 0.03 | F96: 0.04 | G96: 0.02 | H96: 0.11 | I96: 0.04 | J96: 0.04 | K96: 0.07 | L96: 0.07 | M96: =VLOOKUP(A96,Product_Mapping!$B:$D,3,FALSE) -> Sanitary
A97: 6907 | B97: Ceramic flags and paving, hearth or wall tiles; ceramic mosaic cubes and the like, whether or not on a backing (excl. of siliceous fossil meals or similar siliceous earths, refractory goods, tiles specially adapted as table mats, ornamental articles and tiles specifically manufactured for stoves) | C97: 0 | D97: 0.14 | E97: 0.36 | F97: 0.28 | G97: 0.01 | H97: 0.01 | I97: ≈ 0 | J97: 0.01 | K97: 0 | L97: 0.03 | M97: =VLOOKUP(A97,Product_Mapping!$B:$D,3,FALSE) -> Sanitary
A98: 6905 | B98: Roofing tiles, chimney pots, cowls, chimney liners, architectural ornaments and other ceramic constructional goods (excl. of siliceous fossil meals or similar siliceous earths, refractory ceramic constructional components, pipes and other components for drainage and similar purposes) | C98: 0.01 | D98: 0.02 | E98: 0.02 | F98: 0.04 | G98: 0.05 | H98: 0.09 | I98: 0.06 | J98: 0.03 | K98: 0.04 | L98: 0.03 | M98: =VLOOKUP(A98,Product_Mapping!$B:$D,3,FALSE) -> Sanitary
A99: 6906 | B99: Ceramic pipes, conduits, guttering and pipe fittings (excluding of siliceous fossil meals or similar siliceous earths, refractory ceramic goods, chimney liners, pipes specifically manufactured for laboratories, insulating tubing and fittings and other piping for electrotechnical purposes) | C99: 0 | D99: 0 | E99: 0 | F99: 0.01 | G99: 0 | H99: 0.03 | I99: 0.03 | J99: 0.06 | K99: 0.02 | L99: 0.01 | M99: =VLOOKUP(A99,Product_Mapping!$B:$D,3,FALSE) -> Sanitary
A100: 6904 | B100: Ceramic building bricks, flooring blocks, support or filler tiles and the like (excl. those of siliceous fossil meals or similar siliceous earths, refractory bricks of heading 6902, and flags and pavings, hearth and wall tiles of heading 6907 and 6908) | C100: 0.56 | D100: 0.02 | E100: 0 | F100: 1.17 | G100: 0.01 | H100: 0 | I100: 0 | J100: 0 | K100: 0 | L100: 0.01 | M100: =VLOOKUP(A100,Product_Mapping!$B:$D,3,FALSE) -> Sanitary
A101: 6913 | B101: Statuettes and other ornamental ceramic articles, n.e.s. | C101: 0.01 | D101: 0 | E101: 0 | F101: ≈ 0 | G101: 0 | H101: ≈ 0 | I101: 0 | J101: ≈ 0 | K101: 0 | L101: 0 | M101: =VLOOKUP(A101,Product_Mapping!$B:$D,3,FALSE) -> Sanitary
A102: 6901 | B102: Bricks, blocks, tiles and other ceramic goods of siliceous fossil meals, e.g. kieselguhr, tripolite or diatomite, or of similar siliceous earths | C102: 0 | D102: 0.03 | E102: 0.09 | F102: 0.01 | G102: ≈ 0 | H102: 0 | I102: 0 | J102: 0 | K102: 0 | L102: 0 | M102: =VLOOKUP(A102,Product_Mapping!$B:$D,3,FALSE) -> Sanitary
A103: 6908 | B103: Glazed ceramic flags and paving, hearth or wall tiles; glazed ceramic mosaic cubes and the like, whether or not on a backing (excluding of siliceous fossil meals or similar siliceous earths, refractory ceramic goods, tiles specially adapted as table mats, ornamental articles and tiles specifically manufactured for stoves) | C103: 0.02 | D103: 0 | E103: 0 | F103: 0 | G103: 0 | H103: 0 | I103: 0 | J103: 0 | K103: 0 | L103: 0 | M103: =VLOOKUP(A103,Product_Mapping!$B:$D,3,FALSE) -> Sanitary
A104: 7318 | B104: Screws, bolts, nuts, coach screws, screw hooks, rivets, cotters, cotter pins, washers, incl. spring washers, and similar articles, of iron or steel (excl. lag screws, stoppers, plugs and the like, threaded) | C104: 113.57 | D104: 117.43 | E104: 132.84 | F104: 101.88 | G104: 72.63 | H104: 108.66 | I104: 106.46 | J104: 129.47 | K104: 126.9 | L104: 149.87 | M104: =VLOOKUP(A104,Product_Mapping!$B:$D,3,FALSE) -> Hardware
A105: 7302 | B105: Railway or tramway track construction material of iron or steel, the following : rails, check-rails and rack rails, switch blades, crossing frogs, point rods and other crossing pieces, sleepers "cross-ties", fish-plates, chairs, chair wedges, sole plates "base plates", rail clips, bedplates, ties and other material specialised for jointing or fixing rails | C105: 50.07 | D105: 25.71 | E105: 59.5 | F105: 84.44 | G105: 25.54 | H105: 56.81 | I105: 27.73 | J105: 93.62 | K105: 46.06 | L105: 91.28 | M105: =VLOOKUP(A105,Product_Mapping!$B:$D,3,FALSE) -> Hardware
A106: 7326 | B106: Articles of iron or steel, n.e.s. (excl. cast articles) | C106: 69.65 | D106: 64.56 | E106: 59.45 | F106: 65.71 | G106: 40.45 | H106: 55.75 | I106: 53.83 | J106: 60.07 | K106: 62.97 | L106: 79.33 | M106: =VLOOKUP(A106,Product_Mapping!$B:$D,3,FALSE) -> Hardware
A107: 7304 | B107: Tubes, pipes and hollow profiles, seamless, of iron or steel (excl. products of cast iron) | C107: 61.05 | D107: 28.89 | E107: 67.03 | F107: 57.11 | G107: 32.33 | H107: 18.18 | I107: 39.03 | J107: 23.76 | K107: 46.27 | L107: 26.71 | M107: =VLOOKUP(A107,Product_Mapping!$B:$D,3,FALSE) -> Hardware
A108: 7307 | B108: Tube or pipe fittings "e.g. couplings, elbows, sleeves", of iron or steel | C108: 8.38 | D108: 10.37 | E108: 13.63 | F108: 11.21 | G108: 7.98 | H108: 10.59 | I108: 11.38 | J108: 13.39 | K108: 11.34 | L108: 14.93 | M108: =VLOOKUP(A108,Product_Mapping!$B:$D,3,FALSE) -> Hardware
A109: 7320 | B109: Springs and leaves for springs, of iron or steel (excl. clock and watch springs, springs for sticks and handles of umbrellas or parasols, shock absorbers and torque rod or torsion bar springs of Section 17) | C109: 14.32 | D109: 15.14 | E109: 15.84 | F109: 13.38 | G109: 11.05 | H109: 13.72 | I109: 12.57 | J109: 13.42 | K109: 15.07 | L109: 14.46 | M109: =VLOOKUP(A109,Product_Mapping!$B:$D,3,FALSE) -> Hardware
...

Sheet TS_Exports
A1: HS6 Code | B1: Product Description | C1: 2016 | D1: 2017 | E1: 2018 | F1: 2019 | G1: 2020 | H1: 2021 | I1: 2022 | J1: 2023 | K1: 2024 | L1: 2025 | M1: Product Category
A2: 8517 | B2: Telephone sets, incl. smartphones and other telephones for cellular networks or for other wireless networks; other apparatus for the transmission or reception of voice, images or other data, incl. apparatus for communication in a wired or wireless network, parts thereof (excl. transmission or reception apparatus of heading 8443, 8525, 8527 or 8528) | C2: 5.33 | D2: 3.79 | E2: 1.71 | F2: 1.75 | G2: 1.76 | H2: 202.18 | I2: 275.29 | J2: 96.42 | K2: 299.04 | L2: 305.65 | M2: =VLOOKUP(A2,Product_Mapping!$B:$D,3,FALSE) -> Electrical
A3: 8544 | B3: Insulated "incl. enamelled or anodised" wire, cable "incl. coaxial cable" and other insulated electric conductors, whether or not fitted with connectors; optical fibre cables, made up of individually sheathed fibres, whether or not assembled with electric conductors or fitted with connectors | C3: 24.49 | D3: 13.66 | E3: 11.23 | F3: 17.31 | G3: 20.43 | H3: 32.26 | I3: 41.14 | J3: 44.59 | K3: 41.82 | L3: 46.2 | M3: =VLOOKUP(A3,Product_Mapping!$B:$D,3,FALSE) -> Electrical
A4: 8511 | B4: Electrical ignition or starting equipment of a kind used for spark-ignition or compression-ignition internal combustion engines, e.g. ignition magnetos, magneto-dynamos, ignition coils, sparking plugs, glow plugs and starter motors; generators, e.g. dynamos and alternators, and cut-outs of a kind used in conjunction with such engines; parts thereof | C4: 4.38 | D4: 6 | E4: 6.05 | F4: 6.32 | G4: 7.33 | H4: 11.21 | I4: 18.73 | J4: 25.59 | K4: 30.18 | L4: 34.89 | M4: =VLOOKUP(A4,Product_Mapping!$B:$D,3,FALSE) -> Electrical
A5: 8504 | B5: Electrical transformers, static converters, e.g. rectifiers, and inductors; parts thereof | C5: 7.37 | D5: 9.42 | E5: 12.95 | F5: 18.9 | G5: 11.68 | H5: 10.94 | I5: 13.36 | J5: 22.94 | K5: 22.63 | L5: 34.87 | M5: =VLOOKUP(A5,Product_Mapping!$B:$D,3,FALSE) -> Electrical
A6: 8507 | B6: Electric accumulators, incl. separators therefor, whether or not square or rectangular; parts thereof (excl. spent and those of unhardened rubber or textiles) | C6: 0.98 | D6: 1.35 | E6: 1.18 | F6: 0.33 | G6: 0.29 | H6: 5.26 | I6: 12.6 | J6: 35.4 | K6: 15 | L6: 26.19 | M6: =VLOOKUP(A6,Product_Mapping!$B:$D,3,FALSE) -> Electrical
A7: 8527 | B7: Reception apparatus for radio-broadcasting, whether or not combined, in the same housing, with sound recording or reproducing apparatus or a clock | C7: 0.03 | D7: 0.06 | E7: 0.08 | F7: 0.12 | G7: 0.05 | H7: 0.04 | I7: 2.15 | J7: 7.41 | K7: 16.18 | L7: 21.74 | M7: =VLOOKUP(A7,Product_Mapping!$B:$D,3,FALSE) -> Electrical
A8: 8525 | B8: Transmission apparatus for radio-broadcasting or television, whether or not incorporating reception apparatus or sound recording or reproducing apparatus; television cameras, digital cameras and video camera recorders | C8: 0.42 | D8: 0.31 | E8: 0.24 | F8: 0.99 | G8: 2.18 | H8: 0.39 | I8: 1.1 | J8: 3.1 | K8: 3.6 | L8: 20.38 | M8: =VLOOKUP(A8,Product_Mapping!$B:$D,3,FALSE) -> Electrical
A9: 8545 | B9: Carbon electrodes, carbon brushes, lamp carbons, battery carbons and other articles of graphite or other carbon, with or without metal, of a kind used for electrical purposes | C9: 1.6 | D9: 2.77 | E9: 4.34 | F9: 3.12 | G9: 2.99 | H9: 5.61 | I9: 4.92 | J9: 5.7 | K9: 8.15 | L9: 18.85 | M9: =VLOOKUP(A9,Product_Mapping!$B:$D,3,FALSE) -> Electrical
A10: 8537 | B10: Boards, panels, consoles, desks, cabinets and other bases, equipped with two or more apparatus of heading 8535 or 8536, for electric control or the distribution of electricity, incl. those incorporating instruments or apparatus of chapter 90, and numerical control apparatus (excl. switching apparatus for line telephony or line telegraphy) | C10: 33.79 | D10: 36.01 | E10: 39.65 | F10: 28.45 | G10: 18.43 | H10: 20.93 | I10: 23.66 | J10: 16.45 | K10: 15.14 | L10: 15.1 | M10: =VLOOKUP(A10,Product_Mapping!$B:$D,3,FALSE) -> Electrical
A11: 8536 | B11: Electrical apparatus for switching or protecting electrical circuits, or for making connections to or in electrical circuits, e.g., switches, relays, fuses, surge suppressors, plugs, sockets, lamp holders and junction boxes, for a voltage <= 1.000 V (excl. control desks, cabinets, panels etc. of heading 8537) | C11: 5.51 | D11: 5.54 | E11: 6.94 | F11: 6.94 | G11: 7.21 | H11: 9.53 | I11: 11.59 | J11: 9.45 | K11: 8.34 | L11: 9.92 | M11: =VLOOKUP(A11,Product_Mapping!$B:$D,3,FALSE) -> Electrical
A12: 8501 | B12: Electric motors and generators (excl. generating sets) | C12: 7.13 | D12: 4.77 | E12: 4.06 | F12: 5.62 | G12: 3.42 | H12: 7.57 | I12: 5.76 | J12: 5.44 | K12: 8.18 | L12: 7.9 | M12: =VLOOKUP(A12,Product_Mapping!$B:$D,3,FALSE) -> Electrical
A13: 8512 | B13: Electrical lighting or signalling equipment (excl. lamps of heading 8539), windscreen wipers, defrosters and demisters, of a kind used for cycles or motor vehicles; parts thereof | C13: 4.64 | D13: 4.6 | E13: 17.25 | F13: 4.46 | G13: 3.57 | H13: 6.62 | I13: 12.9 | J13: 10.05 | K13: 7.56 | L13: 7.02 | M13: =VLOOKUP(A13,Product_Mapping!$B:$D,3,FALSE) -> Electrical
... A39: 8547 | B39: Insulating fittings for electrical machines, appliances or equipment, being fittings wholly of insulating material apart from any minor components of metal, e.g., threaded sockets, incorporated during moulding solely for purposes of assembly (other than insulators of heading 8546); electrical conduit tubing and joints therefor, of base metal lined with insulating material | C39: 0.04 | D39: 0.13 | E39: 0.04 | F39: 0.09 | G39: 0.02 | H39: 0.02 | I39: 0.03 | J39: 0.04 | K39: 0.02 | L39: 0.04 | M39: =VLOOKUP(A39,Product_Mapping!$B:$D,3,FALSE) -> Electrical
A40: 8521 | B40: Video recording or reproducing apparatus, whether or not incorporating a video tuner (excl. video camera recorders) | C40: 0.01 | D40: 0.02 | E40: 0.02 | F40: 0 | G40: 0.02 | H40: 0.02 | I40: 0.02 | J40: 0 | K40: ≈ 0 | L40: 0.02 | M40: =VLOOKUP(A40,Product_Mapping!$B:$D,3,FALSE) -> Electrical
A41: 8524 | B41: Flat panel display modules, whether or not incorporating touch-sensitive screens | C41: 0 | D41: 0 | E41: 0 | F41: 0 | G41: 0 | H41: 0 | I41: 0.01 | J41: 0.04 | K41: 0.04 | L41: 0.02 | M41: =VLOOKUP(A41,Product_Mapping!$B:$D,3,FALSE) -> Electrical
A42: 8508 | B42: Vacuum cleaners, incl. dry cleaners and wet vacuum cleaners | C42: 0.09 | D42: 0.08 | E42: 0.06 | F42: 0.07 | G42: 0.07 | H42: 0.05 | I42: 0.07 | J42: 0.12 | K42: 0.03 | L42: 0.02 | M42: =VLOOKUP(A42,Product_Mapping!$B:$D,3,FALSE) -> Electrical
A43: 8548 | B43: Waste and scrap of primary cells, primary batteries and electric accumulators; spent primary cells, spent primary batteries and spent electric accumulators; electrical parts of machinery or apparatus, not specified or included elsewhere in chapter 85 | C43: ≈ 0 | D43: 0 | E43: 0 | F43: 0.15 | G43: 0.06 | H43: 0.02 | I43: 0.02 | J43: 0.02 | K43: 0.01 | L43: 0.01 | M43: =VLOOKUP(A43,Product_Mapping!$B:$D,3,FALSE) -> Electrical
A44: 8509 | B44: Electromechanical domestic appliances, with self-contained electric motor; parts thereof (excl. vacuum cleaners, dry and wet vacuum cleaners) | C44: 0 | D44: 0.01 | E44: 0 | F44: 0 | G44: 0 | H44: 0 | I44: 0.02 | J44: 0 | K44: 0 | L44: 0.01 | M44: =VLOOKUP(A44,Product_Mapping!$B:$D,3,FALSE) -> Electrical
A45: 8522 | B45: Parts and accessories suitable for use solely or principally with sound reproducing and recording apparatus and with video equipment for recording and reproducing pictures and sound | C45: 0.01 | D45: 0.03 | E45: 0.01 | F45: 0.01 | G45: 0 | H45: 0 | I45: 0 | J45: 0 | K45: 0.02 | L45: 0 | M45: =VLOOKUP(A45,Product_Mapping!$B:$D,3,FALSE) -> Electrical
A46: 8510 | B46: Electric shavers, hair clippers and hair-removing appliances, with self-contained electric motor; parts thereof | C46: 0 | D46: 0 | E46: 0 | F46: 0 | G46: 0 | H46: 0 | I46: ≈ 0 | J46: 0 | K46: 0 | L46: 0 | M46: =VLOOKUP(A46,Product_Mapping!$B:$D,3,FALSE) -> Electrical
A47: 8519 | B47: Sound recording or sound reproducing apparatus | C47: 0.03 | D47: 0.03 | E47: 0.03 | F47: 0.01 | G47: 0.08 | H47: 0.01 | I47: 0.02 | J47: 0 | K47: 0.05 | L47: 0 | M47: =VLOOKUP(A47,Product_Mapping!$B:$D,3,FALSE) -> Electrical
A48: 8506 | B48: Primary cells and primary batteries, electrical; parts thereof (excl. spent) | C48: 0.02 | D48: 0.02 | E48: 0.04 | F48: 0.01 | G48: 0 | H48: 0.01 | I48: 0 | J48: 0.01 | K48: 0.01 | L48: 0 | M48: =VLOOKUP(A48,Product_Mapping!$B:$D,3,FALSE) -> Electrical
A49: 8513 | B49: Portable electric lamps designed to function by their own source of energy, e.g. dry batteries, accumulators and magnetos; parts thereof (excl. lighting equipment of heading 8512) | C49: 0 | D49: ≈ 0 | E49: ≈ 0 | F49: 0.01 | G49: 0 | H49: ≈ 0 | I49: ≈ 0 | J49: 0.01 | K49: 0 | L49: 0 | M49: =VLOOKUP(A49,Product_Mapping!$B:$D,3,FALSE) -> Electrical
A50: 3926 | B50: Articles of plastics and articles of other materials of heading 3901 to 3914, n.e.s. | C50: 11.63 | D50: 10.99 | E50: 13.05 | F50: 12.29 | G50: 6.59 | H50: 7.51 | I50: 9.71 | J50: 19.29 | K50: 20.39 | L50: 22.26 | M50: =VLOOKUP(A50,Product_Mapping!$B:$D,3,FALSE) -> Plastics
A51: 3904 | B51: Polymers of vinyl chloride or of other halogenated olefins, in primary forms | C51: 0.51 | D51: 1.14 | E51: 3.73 | F51: 5.26 | G51: 3.37 | H51: 6.74 | I51: 17.35 | J51: 16.09 | K51: 23.37 | L51: 16.81 | M51: =VLOOKUP(A51,Product_Mapping!$B:$D,3,FALSE) -> Plastics
A52: 3911 | B52: Petroleum resins, coumarone-indene resins, polyterpenes, polysulphides, polysulphones and other polymers and prepolymers produced by chemical synthesis, n.e.s., in primary forms | C52: 1.27 | D52: 1.84 | E52: 6.28 | F52: 8.68 | G52: 11.47 | H52: 7.17 | I52: 3.44 | J52: 10.64 | K52: 14.17 | L52: 13.11 | M52: =VLOOKUP(A52,Product_Mapping!$B:$D,3,FALSE) -> Plastics
A53: 3920 | B53: Plates, sheets, film, foil and strip, of non-cellular plastics, not reinforced, laminated, supported or similarly combined with other materials, without backing, unworked or merely surface-worked or merely cut into squares or rectangles (excl. self-adhesive products, and floor, wall and ceiling coverings of heading 3918) | C53: 1.39 | D53: 1.38 | E53: 2.06 | F53: 2.11 | G53: 2.4 | H53: 4.95 | I53: 4.48 | J53: 5.75 | K53: 9.81 | L53: 10.93 | M53: =VLOOKUP(A53,Product_Mapping!$B:$D,3,FALSE) -> Plastics
A54: 3923 | B54: Articles for the conveyance or packaging of goods, of plastics; stoppers, lids, caps and other closures, of plastics | C54: 4.76 | D54: 3.38 | E54: 5.13 | F54: 7.62 | G54: 4.52 | H54: 7.17 | I54: 6.61 | J54: 6.09 | K54: 7.49 | L54: 10.08 | M54: =VLOOKUP(A54,Product_Mapping!$B:$D,3,FALSE) -> Plastics
A55: 3907 | B55: Polyacetals, other polyethers and epoxide resins, in primary forms; polycarbonates, alkyd resins, polyallyl esters and other polyesters, in primary forms | C55: 2.06 | D55: 17.05 | E55: 82.22 | F55: 59.8 | G55: 32.38 | H55: 10.35 | I55: 19.25 | J55: 23.59 | K55: 16.1 | L55: 9.58 | M55: =VLOOKUP(A55,Product_Mapping!$B:$D,3,FALSE) -> Plastics
A56: 3917 | B56: Tubes, pipes and hoses, and fittings therefor, e.g. joints, elbows, flanges, of plastics | C56: 0.03 | D56: 0.13 | E56: 0.28 | F56: 0.22 | G56: 0.23 | H56: 0.33 | I56: 0.71 | J56: 2.37 | K56: 4.34 | L56: 5.45 | M56: =VLOOKUP(A56,Product_Mapping!$B:$D,3,FALSE) -> Plastics
A57: 3908 | B57: Polyamides, in primary forms | C57: 6.65 | D57: 8.69 | E57: 9.87 | F57: 8.46 | G57: 4.81 | H57: 6.13 | I57: 5.26 | J57: 7.61 | K57: 5.92 | L57: 3.33 | M57: =VLOOKUP(A57,Product_Mapping!$B:$D,3,FALSE) -> Plastics
A58: 3914 | B58: Ion-exchangers based on polymers of heading 3901 to 3913, in primary forms | C58: 0.86 | D58: 1.04 | E58: 1.53 | F58: 1.81 | G58: 1.86 | H58: 2.56 | I58: 2.42 | J58: 2.05 | K58: 1.94 | L58: 1.86 | M58: =VLOOKUP(A58,Product_Mapping!$B:$D,3,FALSE) -> Plastics
A59: 3903 | B59: Polymers of styrene, in primary forms | C59: 0.31 | D59: 0.19 | E59: 0.11 | F59: 0.15 | G59: 0.24 | H59: 0.07 | I59: 0.05 | J59: 0.98 | K59: 2.22 | L59: 1.78 | M59: =VLOOKUP(A59,Product_Mapping!$B:$D,3,FALSE) -> Plastics
A60: 3921 | B60: Plates, sheets, film, foil and strip, of plastics, reinforced, laminated, supported or similarly combined with other materials, or of cellular plastic, unworked or merely surface-worked or merely cut into squares or rectangles (excl. self-adhesive products, floor, wall and ceiling coverings of heading 3918) | C60: 0.03 | D60: 0.01 | E60: 0.03 | F60: 0.03 | G60: 0.09 | H60: 0.11 | I60: 0.53 | J60: 0.36 | K60: 0.25 | L60: 0.74 | M60: =VLOOKUP(A60,Product_Mapping!$B:$D,3,FALSE) -> Plastics
A61: 3913 | B61: Natural polymers, e.g. alginic acid, and modified natural polymers, e.g. hardened proteins, chemical derivatives of natural rubber, n.e.s., in primary forms | C61: 0.11 | D61: 0.18 | E61: 0.23 | F61: 0.17 | G61: 0.15 | H61: 0.22 | I61: 0.29 | J61: 0.34 | K61: 0.57 | L61: 0.73 | M61: =VLOOKUP(A61,Product_Mapping!$B:$D,3,FALSE) -> Plastics
... A71: 3901 | B71: Polymers of ethylene, in primary forms | C71: 0.02 | D71: 0.22 | E71: 0.2 | F71: 0.53 | G71: 0.03 | H71: 0 | I71: 0.18 | J71: 0.22 | K71: 0 | L71: 0.08 | M71: =VLOOKUP(A71,Product_Mapping!$B:$D,3,FALSE) -> Plastics
A72: 3918 | B72: Floor coverings of plastics, whether or not self-adhesive, in rolls or in the form of tiles; wall or ceiling coverings of plastics, in rolls with a width of >= 45 cm, consisting of a layer of plastics fixed permanently on a backing of any material other than paper, the face side of which is grained, embossed, coloured, design-printed or otherwise decorated | C72: 0.1 | D72: 0.14 | E72: 0.04 | F72: 0.21 | G72: 0.05 | H72: 0 | I72: ≈ 0 | J72: 0 | K72: 0 | L72: 0.01 | M72: =VLOOKUP(A72,Product_Mapping!$B:$D,3,FALSE) -> Plastics
A73: 3922 | B73: Baths, shower-baths, sinks, washbasins, bidets, lavatory pans, seats and covers, flushing cisterns and similar sanitary ware, of plastics | C73: ≈ 0 | D73: ≈ 0 | E73: 0 | F73: 0 | G73: ≈ 0 | H73: ≈ 0 | I73: ≈ 0 | J73: ≈ 0 | K73: 0 | L73: 0 | M73: =VLOOKUP(A73,Product_Mapping!$B:$D,3,FALSE) -> Plastics
A74: 3925 | B74: Builders' ware of plastics, n.e.s. | C74: 0.01 | D74: 0.18 | E74: 0.19 | F74: 0.09 | G74: ≈ 0 | H74: ≈ 0 | I74: 0 | J74: 0.03 | K74: 0 | L74: 0 | M74: =VLOOKUP(A74,Product_Mapping!$B:$D,3,FALSE) -> Plastics
...

Sheet TI_Imports
A1: HS6 Code | B1: Product Descripton | C1: Import Value (USD Thousands) | D1: Quantity | E1: Units | F1: Unit Valure | G1: Units2 | H1: Share in India's imports (%) | I1: Annual growth in import (2021-2025) (%) | J1: Annual growth in quantity (2021-2025)
A2: 8542 | B2: Electronic integrated circuits; parts thereof | C2: 445839 | D2: 645673690 | E2: Units | F2: 0.69 | G2: Units | H2: 1.56 | I2: 33 | J2: n/a
A3: 8536 | B3: Electrical apparatus for switching or protecting electrical circuits, or for making connections to or in electrical circuits, e.g., switches, relays, fuses, surge suppressors, plugs, sockets, lamp holders and junction boxes, for a voltage <= 1.000 V (excl. control desks, cabinets, panels etc. of heading 8537) | C3: 247932 | D3: 6522195392 | E3: Units | F3: 0.04 | G3: Units | H3: 7.25 | I3: 10 | J3: n/a
A4: 8541 | B4: Semiconductor devices "e.g. diodes, transistors, semiconductor-based transducers"; photosensitive semiconductor devices, incl. photovoltaic cells whether or not assembled in modules or made up into panels (excl. photovoltaic generators); light emitting diodes "LED", whether or not assembled with other light-emitting diodes "LED"; mounted piezoelectric crystals; parts thereof | C4: 219166 | D4: 1712779972 | E4: Units | F4: 0.13 | G4: Units | H4: 3.62 | I4: 17 | J4: n/a
A5: 8504 | B5: Electrical transformers, static converters, e.g. rectifiers, and inductors; parts thereof | C5: 161210 | D5: 0 | E5: Mixed | F5: n/a | G5: n/a | H5: 3.76 | I5: 14 | J5: n/a
A6: 8537 | B6: Boards, panels, consoles, desks, cabinets and other bases, equipped with two or more apparatus of heading 8535 or 8536, for electric control or the distribution of electricity, incl. those incorporating instruments or apparatus of chapter 90, and numerical control apparatus (excl. switching apparatus for line telephony or line telegraphy) | C6: 132106 | D6: 3324 | E6: Tons | F6: 39,743.08 | G6: Tons | H6: 9.33 | I6: 2 | J6: 44
A7: 8515 | B7: Electric, incl. electrically heated gas, laser or other light or photon beam, ultrasonic, electron beam, magnetic pulse or plasma arc soldering, brazing or welding machines and apparatus, whether or not capable of cutting; electric machines and apparatus for hot spraying of metals, metal carbides or cermets; parts thereof (excl. guns for spraying hot materials of heading 8424) | C7: 115284 | D7: 0 | E7: Mixed | F7: n/a | G7: n/a | H7: 21.57 | I7: 20 | J7: n/a
A8: 8532 | B8: Electrical capacitors, fixed, variable or adjustable "pre-set"; parts thereof | C8: 115102 | D8: 42430156939 | E8: Units | F8: 0 | G8: Units | H8: 9.28 | I8: 37 | J8: n/a
A9: 8511 | B9: Electrical ignition or starting equipment of a kind used for spark-ignition or compression-ignition internal combustion engines, e.g. ignition magnetos, magneto-dynamos, ignition coils, sparking plugs, glow plugs and starter motors; generators, e.g. dynamos and alternators, and cut-outs of a kind used in conjunction with such engines; parts thereof | C9: 107023 | D9: 0 | E9: Mixed | F9: n/a | G9: n/a | H9: 28.84 | I9: 25 | J9: n/a
A10: 8507 | B10: Electric accumulators, incl. separators therefor, whether or not square or rectangular; parts thereof (excl. spent and those of unhardened rubber or textiles) | C10: 105776 | D10: 0 | E10: Mixed | F10: n/a | G10: n/a | H10: 2.13 | I10: 10 | J10: n/a
A11: 8501 | B11: Electric motors and generators (excl. generating sets) | C11: 79776 | D11: 7419809 | E11: Units | F11: 10.75 | G11: Units | H11: 4.48 | I11: 5 | J11: n/a
A12: 8525 | B12: Transmission apparatus for radio-broadcasting or television, whether or not incorporating reception apparatus or sound recording or reproducing apparatus; television cameras, digital cameras and video camera recorders | C12: 76798 | D12: 857591 | E12: Units | F12: 89.55 | G12: Units | H12: 3.64 | I12: 0 | J12: n/a
A13: 8538 | B13: Parts suitable for use solely or principally with the apparatus of heading 8535, 8536 or 8537, n.e.s. | C13: 74464 | D13: 0 | E13: No | F13: n/a | G13: n/a | H13: 4.71 | I13: 6 | J13: n/a
A14: 8544 | B14: Insulated "incl. enamelled or anodised" wire, cable "incl. coaxial cable" and other insulated electric conductors, whether or not fitted with connectors; optical fibre cables, made up of individually sheathed fibres, whether or not assembled with electric conductors or fitted with connectors | C14: 72371 | D14: 2506501000 | E14: Meters | F14: 288.73 | G14: 1000 meters | H14: 4.26 | I14: 20 | J14: n/a
A15: 8517 | B15: Telephone sets, incl. smartphones and other telephones for cellular networks or for other wireless networks; other apparatus for the transmission or reception of voice, images or other data, incl. apparatus for communication in a wired or wireless network, parts thereof (excl. transmission or reception apparatus of heading 8443, 8525, 8527 or 8528) | C15: 71474 | D15: 191096444 | E15: Units | F15: 0.37 | G15: Units | H15: 0.31 | I15: 10 | J15: n/a
A16: 8543 | B16: Electrical machines and apparatus, having individual functions, n.e.s. in chapter 85 and parts thereof | C16: 59854 | D16: 0 | E16: Mixed | F16: n/a | G16: n/a | H16: 5.19 | I16: 10 | J16: n/a
A17: 8547 | B17: Insulating fittings for electrical machines, appliances or equipment, being fittings wholly of insulating material apart from any minor components of metal, e.g., threaded sockets, incorporated during moulding solely for purposes of assembly (other than insulators of heading 8546); electrical conduit tubing and joints therefor, of base metal lined with insulating material | C17: 56868 | D17: 1922 | E17: Tons | F17: 29,587.93 | G17: Tons | H17: 19.82 | I17: 8 | J17: -19
A18: 8533 | B18: Electrical resistors, incl. rheostats and potentiometers (excl. heating resistors); parts thereof | C18: 36678 | D18: 4802087742 | E18: Units | F18: 0.01 | G18: Units | H18: 7.61 | I18: 21 | J18: n/a
A19: 8512 | B19: Electrical lighting or signalling equipment (excl. lamps of heading 8539), windscreen wipers, defrosters and demisters, of a kind used for cycles or motor vehicles; parts thereof | C19: 34344 | D19: 0 | E19: Mixed | F19: n/a | G19: n/a | H19: 5.82 | I19: 17 | J19: n/a
A20: 8523 | B20: Discs, tapes, solid-state non-volatile storage devices, "smart cards" and other media for the recording of sound or of other phenomena, whether or not recorded, incl. matrices and masters for the production of discs (excl. products of chapter 37) | C20: 33255 | D20: 1283038 | E20: Units | F20: 25.92 | G20: Units | H20: 2.35 | I20: 17 | J20: n/a
A21: 8503 | B21: Parts suitable for use solely or principally with electric motors and generators, electric generating sets and rotary converters, n.e.s. | C21: 29591 | D21: 59891730 | E21: Units | F21: 0.49 | G21: Units | H21: 2.38 | I21: -5 | J21: n/a
A22: 8505 | B22: Electromagnets (excl. magnets for medical use); permanent magnets and articles intended to become permanent magnets after magnetization; electromagnetic or permanent magnet chucks, clamps and similar holding devices; electromagnetic couplings, clutches and brakes; electromagnetic lifting heads; parts thereof | C22: 26216 | D22: 954 | E22: Tons | F22: 27,480.08 | G22: Tons | H22: 5.9 | I22: 16 | J22: -20
A23: 8534 | B23: Printed circuits | C23: 12117 | D23: 5636050 | E23: Units | F23: 2.15 | G23: Units | H23: 0.75 | I23: 11 | J23: n/a
A24: 8514 | B24: Industrial or laboratory electric furnaces and ovens, incl. those functioning by induction or dielectric loss; other industrial or laboratory equipment for the heat treatment of materials by induction or dielectric loss; parts thereof | C24: 11440 | D24: 0 | E24: Mixed | F24: n/a | G24: n/a | H24: 3.91 | I24: 21 | J24: n/a
A25: 8516 | B25: Electric instantaneous or storage water heaters and immersion heaters; electric space-heating apparatus and soil-heating apparatus; electro-thermic hairdressing apparatus, e.g. hairdryers, hair curlers and curling tong heaters, and hand dryers; electric smoothing irons; other electro-thermic appliances of a kind used for domestic purposes; electric heating resistors (other than those of heading 8545); parts thereof | C25: 10107 | D25: 0 | E25: No | F25: n/a | G25: n/a | H25: 1.41 | I25: 11 | J25: n/a
A26: 8540 | B26: Thermionic, cold cathode or photo-cathode valves and tubes, e.g. vacuum or vapour or gas filled valves and tubes, mercury arc rectifying valves and tubes, cathode ray tubes and television camera tubes; parts thereof | C26: 9365 | D26: 3644 | E26: Units | F26: 2,569.98 | G26: Units | H26: 21.56 | I26: 21 | J26: n/a
A27: 8545 | B27: Carbon electrodes, carbon brushes, lamp carbons, battery carbons and other articles of graphite or other carbon, with or without metal, of a kind used for electrical purposes | C27: 8380 | D27: 1632 | E27: Tons | F27: 5,134.8 | G27: Tons | H27: 2.7 | I27: -9 | J27: -5
A28: 8528 | B28: Monitors and projectors, not incorporating television reception apparatus; reception apparatus for television, whether or not incorporating radio-broadcast receivers or sound or video recording or reproducing apparatus | C28: 8188 | D28: 18783 | E28: Units | F28: 435.93 | G28: Units | H28: 0.78 | I28: 5 | J28: n/a
A29: 8530 | B29: Electrical signalling, safety or traffic control equipment for railways, tramways, roads, inland waterways, parking facilities, port installations or airfields (excl. mechanical or electromechanical equipment of heading 8608); parts thereof | C29: 8012 | D29: 0 | E29: Mixed | F29: n/a | G29: n/a | H29: 7.55 | I29: 2 | J29: n/a
A30: 8518 | B30: Microphones and stands therefor (excl. cordless microphones with built-in transmitter); loudspeakers, whether or not mounted in their enclosures; headphones and earphones, whether or not combined with a microphone, and sets consisting of a microphone and one or more loudspeakers (excl. telephone sets, hearing aids and helmets with built-in headphones, whether or not incorporating a microphone); audio-frequency electric amplifiers; electric sound amplifier sets; parts thereof | C30: 7806 | D30: 0 | E30: No | F30: n/a | G30: n/a | H30: 0.4 | I30: 18 | J30: n/a
A31: 8539 | B31: Electric filament or discharge lamps, incl. sealed beam lamp units and ultraviolet or infra-red lamps; arc lamps; light-emitting diode "LED" light sources; parts thereof | C31: 7029 | D31: 0 | E31: No | F31: n/a | G31: n/a | H31: 5.59 | I31: -8 | J31: n/a
A32: 8506 | B32: Primary cells and primary batteries, electrical; parts thereof (excl. spent) | C32: 6550 | D32: 28652225 | E32: Units | F32: 0.23 | G32: Units | H32: 5.68 | I32: 21 | J32: n/a
A33: 8531 | B33: Electric sound or visual signalling apparatus, e.g. bells, sirens, indicator panels, burglar or fire alarms (excl. those for cycles, motor vehicles and traffic signalling); parts thereof | C33: 2966 | D33: 0 | E33: No | F33: n/a | G33: n/a | H33: 0.9 | I33: 2 | J33: n/a
A34: 8546 | B34: Electrical insulators of any material (excl. insulating fittings) | C34: 2286 | D34: 119 | E34: Tons | F34: 19,210.08 | G34: Tons | H34: 1.46 | I34: 22 | J34: 61
A35: 8529 | B35: Parts suitable for use solely or principally with flat panel display modules, transmission and reception apparatus for radio-telephony, radio-telegraphy, radio-broadcasting, television, television cameras, still image video cameras and other video camera recorders, radar apparatus, radio navigational aid apparatus or radio remote control apparatus, n.e.s. | C35: 2109 | D35: 722026 | E35: Units | F35: 2.92 | G35: Units | H35: 0.82 | I35: -41 | J35: n/a
A36: 8535 | B36: Electrical apparatus for switching or protecting electrical circuits, or for making connections to or in electrical circuits, e.g., switches, fuses, lightning arresters, voltage limiters, surge suppressors, plugs and other connectors, junction boxes, for a voltage > 1.000 V (excl. control desks, cabinets, panels etc. of heading 8537) | C36: 1463 | D36: 6695052 | E36: Units | F36: 0.22 | G36: Units | H36: 0.4 | I36: 1 | J36: n/a
A37: 8527 | B37: Reception apparatus for radio-broadcasting, whether or not combined, in the same housing, with sound recording or reproducing apparatus or a clock | C37: 1398 | D37: 3373 | E37: Units | F37: 414.47 | G37: Units | H37: 0.47 | I37: 47 | J37: n/a
A38: 8526 | B38: Radar apparatus, radio navigational aid apparatus and radio remote control apparatus | C38: 653 | D38: 2273 | E38: Units | F38: 287.29 | G38: Units | H38: 0.33 | I38: 48 | J38: n/a
A39: 8521 | B39: Video recording or reproducing apparatus, whether or not incorporating a video tuner (excl. video camera recorders) | C39: 607 | D39: 496 | E39: Units | F39: 1,223.79 | G39: Units | H39: 1.55 | I39: 12 | J39: -80
A40: 8508 | B40: Vacuum cleaners, incl. dry cleaners and wet vacuum cleaners | C40: 469 | D40: 0 | E40: No | F40: n/a | G40: n/a | H40: 0.26 | I40: 60 | J40: n/a
...

Sheet TI_Exports
A1: HS6 code | B1: Product Description | C1: Export Value (USD Thousands) | D1: Quantity | E1: Units | F1: Unit Value | G1: Units2 | H1: Share in India's exports (%) | I1: Annual growth in export (2021-2025) (%) | J1: Annual growth in quantity (2021-2025)
A2: 8517 | B2: Telephone sets, incl. smartphones and other telephones for cellular networks or for other wireless networks; other apparatus for the transmission or reception of voice, images or other data, incl. apparatus for communication in a wired or wireless network, parts thereof (excl. transmission or reception apparatus of heading 8443, 8525, 8527 or 8528) | C2: 306416 | D2: 711590 | E2: Units | F2: 430.61 | G2: Units | H2: 0.91 | I2: 10 | J2: n/a
A3: 8544 | B3: Insulated "incl. enamelled or anodised" wire, cable "incl. coaxial cable" and other insulated electric conductors, whether or not fitted with connectors; optical fibre cables, made up of individually sheathed fibres, whether or not assembled with electric conductors or fitted with connectors | C3: 46314 | D3: 527861000 | E3: Meters | F3: 877.39 | G3: 1000 meters | H3: 1.68 | I3: 8 | J3: n/a
A4: 8504 | B4: Electrical transformers, static converters, e.g. rectifiers, and inductors; parts thereof | C4: 35036 | D4: 0 | E4: Mixed | H4: 1.12 | I4: 33 | J4: n/a
A5: 8511 | B5: Electrical ignition or starting equipment of a kind used for spark-ignition or compression-ignition internal combustion engines, e.g. ignition magnetos, magneto-dynamos, ignition coils, sparking plugs, glow plugs and starter motors; generators, e.g. dynamos and alternators, and cut-outs of a kind used in conjunction with such engines; parts thereof | C5: 34910 | D5: 0 | E5: Mixed | H5: 7.29 | I5: 32 | J5: n/a
A6: 8507 | B6: Electric accumulators, incl. separators therefor, whether or not square or rectangular; parts thereof (excl. spent and those of unhardened rubber or textiles) | C6: 26265 | D6: 53033 | E6: Units | F6: 495.26 | G6: Units | H6: 3.62 | I6: 40 | J6: n/a
A7: 8527 | B7: Reception apparatus for radio-broadcasting, whether or not combined, in the same housing, with sound recording or reproducing apparatus or a clock | C7: 21749 | D7: 156753 | E7: Units | F7: 138.75 | G7: Units | H7: 72.03 | I7: 343 | J7: n/a
A8: 8525 | B8: Transmission apparatus for radio-broadcasting or television, whether or not incorporating reception apparatus or sound recording or reproducing apparatus; television cameras, digital cameras and video camera recorders | C8: 20424 | D8: 201240 | E8: Units | F8: 101.49 | G8: Units | H8: 10.66 | I8: 148 | J8: n/a
A9: 8545 | B9: Carbon electrodes, carbon brushes, lamp carbons, battery carbons and other articles of graphite or other carbon, with or without metal, of a kind used for electrical purposes | C9: 18855 | D9: 5648 | E9: Tons | F9: 3,338.35 | G9: Tons | H9: 7.07 | I9: 34 | J9: 50
A10: 8537 | B10: Boards, panels, consoles, desks, cabinets and other bases, equipped with two or more apparatus of heading 8535 or 8536, for electric control or the distribution of electricity, incl. those incorporating instruments or apparatus of chapter 90, and numerical control apparatus (excl. switching apparatus for line telephony or line telegraphy) | C10: 15173 | D10: 144 | E10: Tons | F10: 105,368.06 | G10: Tons | H10: 1.44 | I10: -10 | J10: -7
A11: 8536 | B11: Electrical apparatus for switching or protecting electrical circuits, or for making connections to or in electrical circuits, e.g., switches, relays, fuses, surge suppressors, plugs, sockets, lamp holders and junction boxes, for a voltage <= 1.000 V (excl. control desks, cabinets, panels etc. of heading 8537) | C11: 10015 | D11: 0 | E11: No | H11: 0.68 | I11: -2 | J11: n/a
A12: 8501 | B12: Electric motors and generators (excl. generating sets) | C12: 7953 | D12: 0 | E12: No | H12: 0.9 | I12: 5 | J12: n/a
A13: 8512 | B13: Electrical lighting or signalling equipment (excl. lamps of heading 8539), windscreen wipers, defrosters and demisters, of a kind used for cycles or motor vehicles; parts thereof | C13: 7062 | D13: 0 | E13: Mixed | H13: 2.36 | I13: -4 | J13: n/a
A14: 8503 | B14: Parts suitable for use solely or principally with electric motors and generators, electric generating sets and rotary converters, n.e.s. | C14: 4471 | D14: 294294 | E14: Units | F14: 15.19 | G14: Units | H14: 0.32 | I14: 0 | J14: n/a
A15: 8538 | B15: Parts suitable for use solely or principally with the apparatus of heading 8535, 8536 or 8537, n.e.s. | C15: 3791 | D15: 0 | E15: No | H15: 0.24 | I15: -8 | J15: n/a
A16: 8502 | B16: Electric generating sets and rotary converters | C16: 2504 | D16: 0 | E16: No | H16: 0.32 | I16: 12 | J16: n/a
A17: 8542 | B17: Electronic integrated circuits; parts thereof | C17: 2410 | D17: 0 | E17: No | H17: 0.99 | I17: 25 | J17: n/a
A18: 8546 | B18: Electrical insulators of any material (excl. insulating fittings) | C18: 1743 | D18: 65 | E18: Tons | F18: 26,815.38 | G18: Tons | H18: 0.91 | I18: 0 | J18: 1
A19: 8541 | B19: Semiconductor devices "e.g. diodes, transistors, semiconductor-based transducers"; photosensitive semiconductor devices, incl. photovoltaic cells whether or not assembled in modules or made up into panels (excl. photovoltaic generators); light emitting diodes "LED", whether or not assembled with other light-emitting diodes "LED"; mounted piezoelectric crystals; parts thereof | C19: 1227 | D19: 0 | E19: No | H19: 0.09 | I19: 44 | J19: n/a
A20: 8523 | B20: Discs, tapes, solid-state non-volatile storage devices, "smart cards" and other media for the recording of sound or of other phenomena, whether or not recorded, incl. matrices and masters for the production of discs (excl. products of chapter 37) | C20: 1007 | D20: 0 | E20: No | H20: 0.56 | I20: 29 | J20: n/a
A21: 8543 | B21: Electrical machines and apparatus, having individual functions, n.e.s. in chapter 85 and parts thereof | C21: 802 | D21: 0 | E21: No | H21: 0.3 | I21: 7 | J21: n/a
A22: 8533 | B22: Electrical resistors, incl. rheostats and potentiometers (excl. heating resistors); parts thereof | C22: 713 | D22: 0 | E22: No | H22: 1.23 | I22: 12 | J22: n/a
A23: 8505 | B23: Electromagnets (excl. magnets for medical use); permanent magnets and articles intended to become permanent magnets after magnetization; electromagnetic or permanent magnet chucks, clamps and similar holding devices; electromagnetic couplings, clutches and brakes; electromagnetic lifting heads; parts thereof | C23: 628 | D23: 24 | E23: Tons | F23: 26,166.67 | G23: Tons | H23: 1.04 | I23: 13 | J23: 14
A24: 8518 | B24: Microphones and stands therefor (excl. cordless microphones with built-in transmitter); loudspeakers, whether or not mounted in their enclosures; headphones and earphones, whether or not combined with a microphone, and sets consisting of a microphone and one or more loudspeakers (excl. telephone sets, hearing aids and helmets with built-in headphones, whether or not incorporating a microphone); audio-frequency electric amplifiers; electric sound amplifier sets; parts thereof | C24: 539 | D24: 0 | E24: No | H24: 0.24 | I24: 6 | J24: n/a
A25: 8548 | B25: Waste and scrap of primary cells, primary batteries and electric accumulators; spent primary cells, spent primary batteries and spent electric accumulators; electrical parts of machinery or apparatus, not specified or included elsewhere in chapter 85 | C25: 512 | D25: 0 | E25: No | H25: 18.33 | I25: 170 | J25: n/a
A26: 8528 | B26: Monitors and projectors, not incorporating television reception apparatus; reception apparatus for television, whether or not incorporating radio-broadcast receivers or sound or video recording or reproducing apparatus | C26: 491 | D26: 0 | E26: No | H26: 0.27 | I26: 46 | J26: n/a
A27: 8516 | B27: Electric instantaneous or storage water heaters and immersion heaters; electric space-heating apparatus and soil-heating apparatus; electro-thermic hairdressing apparatus, e.g. hairdryers, hair curlers and curling tong heaters, and hand dryers; electric smoothing irons; other electro-thermic appliances of a kind used for domestic purposes; electric heating resistors (other than those of heading 8545); parts thereof | C27: 372 | D27: 0 | E27: No | H27: 0.24 | I27: -34 | J27: n/a
A28: 8534 | B28: Printed circuits | C28: 306 | D28: 0 | E28: No | H28: 0.18 | I28: 13 | J28: n/a
A29: 8514 | B29: Industrial or laboratory electric furnaces and ovens, incl. those functioning by induction or dielectric loss; other industrial or laboratory equipment for the heat treatment of materials by induction or dielectric loss; parts thereof | C29: 303 | D29: 0 | E29: No | H29: 0.22 | I29: 3 | J29: n/a
A30: 8532 | B30: Electrical capacitors, fixed, variable or adjustable "pre-set"; parts thereof | C30: 244 | D30: 0 | E30: No | H30: 0.16 | I30: -5 | J30: n/a
A31: 8531 | B31: Electric sound or visual signalling apparatus, e.g. bells, sirens, indicator panels, burglar or fire alarms (excl. those for cycles, motor vehicles and traffic signalling); parts thereof | C31: 208 | D31: 0 | E31: No | H31: 0.24 | I31: 106 | J31: n/a
A32: 8540 | B32: Thermionic, cold cathode or photo-cathode valves and tubes, e.g. vacuum or vapour or gas filled valves and tubes, mercury arc rectifying valves and tubes, cathode ray tubes and television camera tubes; parts thereof | C32: 199 | D32: 0 | E32: Mixed | H32: 2.2 | I32: 22 | J32: n/a
A33: 8515 | B33: Electric, incl. electrically heated gas, laser or other light or photon beam, ultrasonic, electron beam, magnetic pulse or plasma arc soldering, brazing or welding machines and apparatus, whether or not capable of cutting; electric machines and apparatus for hot spraying of metals, metal carbides or cermets; parts thereof (excl. guns for spraying hot materials of heading 8424) | C33: 193 | D33: 0 | E33: No | H33: 0.21 | I33: -21 | J33: n/a
A34: 8530 | B34: Electrical signalling, safety or traffic control equipment for railways, tramways, roads, inland waterways, parking facilities, port installations or airfields (excl. mechanical or electromechanical equipment of heading 8608); parts thereof | C34: 145 | D34: 0 | E34: No | H34: 0.46 | I34: -38 | J34: n/a
A35: 8529 | B35: Parts suitable for use solely or principally with flat panel display modules, transmission and reception apparatus for radio-telephony, radio-telegraphy, radio-broadcasting, television, television cameras, still image video cameras and other video camera recorders, radar apparatus, radio navigational aid apparatus or radio remote control apparatus, n.e.s. | C35: 82 | D35: 0 | E35: No | H35: 0.24 | I35: -60 | J35: n/a
... A37: 8535 | B37: Electrical apparatus for switching or protecting electrical circuits, or for making connections to or in electrical circuits, e.g., switches, fuses, lightning arresters, voltage limiters, surge suppressors, plugs and other connectors, junction boxes, for a voltage > 1.000 V (excl. control desks, cabinets, panels etc. of heading 8537) | C37: 53 | D37: 0 | E37: No | H37: 0.02 | I37: -72 | J37: n/a
A38: 8547 | B38: Insulating fittings for electrical machines, appliances or equipment, being fittings wholly of insulating material apart from any minor components of metal, e.g., threaded sockets, incorporated during moulding solely for purposes of assembly (other than insulators of heading 8546); electrical conduit tubing and joints therefor, of base metal lined with insulating material | C38: 48 | D38: 5 | E38: Tons | F38: 9,600 | G38: Tons | H38: 0.07 | I38: 17 | J38: 20
A39: 8539 | B39: Electric filament or discharge lamps, incl. sealed beam lamp units and ultraviolet or infra-red lamps; arc lamps; light-emitting diode "LED" light sources; parts thereof | C39: 41 | D39: 0 | E39: No | H39: 0.09 | I39: -20 | J39: n/a
A40: 8508 | B40: Vacuum cleaners, incl. dry cleaners and wet vacuum cleaners | C40: 37 | D40: 0 | E40: No | H40: 0.49 | I40: -11 | J40: n/a
A41: 8521 | B41: Video recording or reproducing apparatus, whether or not incorporating a video tuner (excl. video camera recorders) | C41: 27 | D41: 0 | E41: No | H41: 1.07 | I41: -13 | J41: n/a
...

Sheet Product_Mapping
A1: HS Chapter | B1: HS6 Code | C1: Product Description | D1: Product Category | E1: Business Function
A2: 85 | B2: 8542 | C2: Electronic integrated circuits; parts thereof | D2: =VLOOKUP(A2,[1]HS_Category_Map!$A$2:$B$10,2,FALSE) -> Electrical | E2: =VLOOKUP(D2,[1]Category_Function_Map!$A$2:$C$7,2,FALSE) -> Electrical Supplies
A3: 85 | B3: 8536 | C3: Electrical apparatus for switching or protecting electrical circuits, or for making connections to or in electrical circuits, e.g., switches, relays, fuses, surge suppressors, plugs, sockets, lamp holders and junction boxes, for a voltage <= 1.000 V (excl. control desks, cabinets, panels etc. of heading 8537) | D3: =VLOOKUP(A3,[1]HS_Category_Map!$A$2:$B$10,2,FALSE) -> Electrical | E3: =VLOOKUP(D3,[1]Category_Function_Map!$A$2:$C$7,2,FALSE) -> Electrical Supplies
A4: 85 | B4: 8541 | C4: Semiconductor devices "e.g. diodes, transistors, semiconductor-based transducers"; photosensitive semiconductor devices, incl. photovoltaic cells whether or not assembled in modules or made up into panels (excl. photovoltaic generators); light emitting diodes "LED", whether or not assembled with other light-emitting diodes "LED"; mounted piezoelectric crystals; parts thereof | D4: =VLOOKUP(A4,[1]HS_Category_Map!$A$2:$B$10,2,FALSE) -> Electrical | E4: =VLOOKUP(D4,[1]Category_Function_Map!$A$2:$C$7,2,FALSE) -> Electrical Supplies
A5: 85 | B5: 8504 | C5: Electrical transformers, static converters, e.g. rectifiers, and inductors; parts thereof | D5: =VLOOKUP(A5,[1]HS_Category_Map!$A$2:$B$10,2,FALSE) -> Electrical | E5: =VLOOKUP(D5,[1]Category_Function_Map!$A$2:$C$7,2,FALSE) -> Electrical Supplies
A6: 85 | B6: 8537 | C6: Boards, panels, consoles, desks, cabinets and other bases, equipped with two or more apparatus of heading 8535 or 8536, for electric control or the distribution of electricity, incl. those incorporating instruments or apparatus of chapter 90, and numerical control apparatus (excl. switching apparatus for line telephony or line telegraphy) | D6: =VLOOKUP(A6,[1]HS_Category_Map!$A$2:$B$10,2,FALSE) -> Electrical | E6: =VLOOKUP(D6,[1]Category_Function_Map!$A$2:$C$7,2,FALSE) -> Electrical Supplies
A7: 85 | B7: 8515 | C7: Electric, incl. electrically heated gas, laser or other light or photon beam, ultrasonic, electron beam, magnetic pulse or plasma arc soldering, brazing or welding machines and apparatus, whether or not capable of cutting; electric machines and apparatus for hot spraying of metals, metal carbides or cermets; parts thereof (excl. guns for spraying hot materials of heading 8424) | D7: =VLOOKUP(A7,[1]HS_Category_Map!$A$2:$B$10,2,FALSE) -> Electrical | E7: =VLOOKUP(D7,[1]Category_Function_Map!$A$2:$C$7,2,FALSE) -> Electrical Supplies
A8: 85 | B8: 8532 | C8: Electrical capacitors, fixed, variable or adjustable "pre-set"; parts thereof | D8: =VLOOKUP(A8,[1]HS_Category_Map!$A$2:$B$10,2,FALSE) -> Electrical | E8: =VLOOKUP(D8,[1]Category_Function_Map!$A$2:$C$7,2,FALSE) -> Electrical Supplies
A9: 85 | B9: 8511 | C9: Electrical ignition or starting equipment of a kind used for spark-ignition or compression-ignition internal combustion engines, e.g. ignition magnetos, magneto-dynamos, ignition coils, sparking plugs, glow plugs and starter motors; generators, e.g. dynamos and alternators, and cut-outs of a kind used in conjunction with such engines; parts thereof | D9: =VLOOKUP(A9,[1]HS_Category_Map!$A$2:$B$10,2,FALSE) -> Electrical | E9: =VLOOKUP(D9,[1]Category_Function_Map!$A$2:$C$7,2,FALSE) -> Electrical Supplies
A10: 85 | B10: 8507 | C10: Electric accumulators, incl. separators therefor, whether or not square or rectangular; parts thereof (excl. spent and those of unhardened rubber or textiles) | D10: =VLOOKUP(A10,[1]HS_Category_Map!$A$2:$B$10,2,FALSE) -> Electrical | E10: =VLOOKUP(D10,[1]Category_Function_Map!$A$2:$C$7,2,FALSE) -> Electrical Supplies
